Workbook

Sheet Dashboard
A1: Horizon AMS Reinvention — First 180 Days Transition Dashboard
A2: Plan start: July 1, 2026 | Scope: Transition, QE, AIOps, CareOps360, Agile/Product model | Update % Complete / Status in Master Plan to refresh tracking views
A4: Total Tasks | B4: =COUNTA('180D Master Plan'!A2:A100) -> 99
A5: Completed | B5: =COUNTIF('180D Master Plan'!M2:M100,"Completed") -> 0
A6: At Risk / Blocked | B6: =COUNTIF('180D Master Plan'!M2:M100,"At Risk")+COUNTIF('180D Master Plan'!M2:M100,"Blocked") -> 0
A7: Avg % Complete | B7: =AVERAGE('180D Master Plan'!O2:O100) -> 0
A8: Critical/High Tasks | B8: =COUNTIF('180D Master Plan'!N2:N100,"Critical")+COUNTIF('180D Master Plan'!N2:N100,"High") -> 99
A11: Workstream | B11: Tasks | C11: Completed | D11: In Progress | E11: At Risk/Blocked | F11: Avg % Complete | H11: Phase | I11: Tasks | J11: Completed
A12: Overall Transition | B12: =COUNTIF('180D Master Plan'!B:B,A12) -> 19 | C12: =COUNTIFS('180D Master Plan'!B:B,A12,'180D Master Plan'!M:M,"Completed") -> 0 | D12: =COUNTIFS('180D Master Plan'!B:B,A12,'180D Master Plan'!M:M,"In Progress") -> 0 | E12: =COUNTIFS('180D Master Plan'!B:B,A12,'180D Master Plan'!M:M,"At Risk")+COUNTIFS('180D Master Plan'!B:B,A12,'180D Master Plan'!M:M,"Blocked") -> 0 | F12: =SUMIF('180D Master Plan'!B:B,A12,'180D Master Plan'!O:O)/B12 -> 0 | H12: 0-30 Foundation | I12: =COUNTIF('180D Master Plan'!C:C,H12) -> 36 | J12: =COUNTIFS('180D Master Plan'!C:C,H12,'180D Master Plan'!M:M,"Completed") -> 0
A13: Quality Engineering | B13: =COUNTIF('180D Master Plan'!B:B,A13) -> 21 | C13: =COUNTIFS('180D Master Plan'!B:B,A13,'180D Master Plan'!M:M,"Completed") -> 0 | D13: =COUNTIFS('180D Master Plan'!B:B,A13,'180D Master Plan'!M:M,"In Progress") -> 0 | E13: =COUNTIFS('180D Master Plan'!B:B,A13,'180D Master Plan'!M:M,"At Risk")+COUNTIFS('180D Master Plan'!B:B,A13,'180D Master Plan'!M:M,"Blocked") -> 0 | F13: =SUMIF('180D Master Plan'!B:B,A13,'180D Master Plan'!O:O)/B13 -> 0 | H13: 31-60 Production Ready | I13: =COUNTIF('180D Master Plan'!C:C,H13) -> 19 | J13: =COUNTIFS('180D Master Plan'!C:C,H13,'180D Master Plan'!M:M,"Completed") -> 0
A14: AIOps Implementation | B14: =COUNTIF('180D Master Plan'!B:B,A14) -> 20 | C14: =COUNTIFS('180D Master Plan'!B:B,A14,'180D Master Plan'!M:M,"Completed") -> 0 | D14: =COUNTIFS('180D Master Plan'!B:B,A14,'180D Master Plan'!M:M,"In Progress") -> 0 | E14: =COUNTIFS('180D Master Plan'!B:B,A14,'180D Master Plan'!M:M,"At Risk")+COUNTIFS('180D Master Plan'!B:B,A14,'180D Master Plan'!M:M,"Blocked") -> 0 | F14: =SUMIF('180D Master Plan'!B:B,A14,'180D Master Plan'!O:O)/B14 -> 0 | H14: 61-90 Standardize & Integrate | I14: =COUNTIF('180D Master Plan'!C:C,H14) -> 19 | J14: =COUNTIFS('180D Master Plan'!C:C,H14,'180D Master Plan'!M:M,"Completed") -> 0
A15: CareOps360 | B15: =COUNTIF('180D Master Plan'!B:B,A15) -> 20 | C15: =COUNTIFS('180D Master Plan'!B:B,A15,'180D Master Plan'!M:M,"Completed") -> 0 | D15: =COUNTIFS('180D Master Plan'!B:B,A15,'180D Master Plan'!M:M,"In Progress") -> 0 | E15: =COUNTIFS('180D Master Plan'!B:B,A15,'180D Master Plan'!M:M,"At Risk")+COUNTIFS('180D Master Plan'!B:B,A15,'180D Master Plan'!M:M,"Blocked") -> 0 | F15: =SUMIF('180D Master Plan'!B:B,A15,'180D Master Plan'!O:O)/B15 -> 0 | H15: 91-180 Scale & Optimize | I15: =COUNTIF('180D Master Plan'!C:C,H15) -> 25 | J15: =COUNTIFS('180D Master Plan'!C:C,H15,'180D Master Plan'!M:M,"Completed") -> 0
A16: Agile Product Model | B16: =COUNTIF('180D Master Plan'!B:B,A16) -> 19 | C16: =COUNTIFS('180D Master Plan'!B:B,A16,'180D Master Plan'!M:M,"Completed") -> 0 | D16: =COUNTIFS('180D Master Plan'!B:B,A16,'180D Master Plan'!M:M,"In Progress") -> 0 | E16: =COUNTIFS('180D Master Plan'!B:B,A16,'180D Master Plan'!M:M,"At Risk")+COUNTIFS('180D Master Plan'!B:B,A16,'180D Master Plan'!M:M,"Blocked") -> 0 | F16: =SUMIF('180D Master Plan'!B:B,A16,'180D Master Plan'!O:O)/B16 -> 0
A20: Month | B20: Milestones Ending | C20: Tasks Starting | D20: Cumulative Tasks Ending | H20: Workstream | I20: Jul | J20: Aug | K20: Sep | L20: Oct | M20: Nov | N20: Dec
A21: 46204 | B21: =COUNTIFS('180D Master Plan'!H:H,">="&A21,'180D Master Plan'!H:H,"<"&EDATE(A21,1)) -> 31 | C21: =COUNTIFS('180D Master Plan'!G:G,">="&A21,'180D Master Plan'!G:G,"<"&EDATE(A21,1)) -> 42 | D21: =COUNTIF('180D Master Plan'!H:H,"<"&EDATE(A21,1)) -> 31 | H21: Overall Transition | I21: =COUNTIFS('180D Master Plan'!B:B,$H21,'180D Master Plan'!G:G,"<"&DATE(2026,8,1),'180D Master Plan'!H:H,">="&DATE(2026,7,1)) -> 10 | J21: =COUNTIFS('180D Master Plan'!B:B,$H21,'180D Master Plan'!G:G,"<"&DATE(2026,9,1),'180D Master Plan'!H:H,">="&DATE(2026,8,1)) -> 6 | K21: =COUNTIFS('180D Master Plan'!B:B,$H21,'180D Master Plan'!G:G,"<"&DATE(2026,10,1),'180D Master Plan'!H:H,">="&DATE(2026,9,1)) -> 4 | L21: =COUNTIFS('180D Master Plan'!B:B,$H21,'180D Master Plan'!G:G,"<"&DATE(2026,11,1),'180D Master Plan'!H:H,">="&DATE(2026,10,1)) -> 3 | M21: =COUNTIFS('180D Master Plan'!B:B,$H21,'180D Master Plan'!G:G,"<"&DATE(2026,12,1),'180D Master Plan'!H:H,">="&DATE(2026,11,1)) -> 3 | N21: =COUNTIFS('180D Master Plan'!B:B,$H21,'180D Master Plan'!G:G,"<"&DATE(2027,1,1),'180D Master Plan'!H:H,">="&DATE(2026,12,1)) -> 2
A22: 46235 | B22: =COUNTIFS('180D Master Plan'!H:H,">="&A22,'180D Master Plan'!H:H,"<"&EDATE(A22,1)) -> 22 | C22: =COUNTIFS('180D Master Plan'!G:G,">="&A22,'180D Master Plan'!G:G,"<"&EDATE(A22,1)) -> 19 | D22: =COUNTIF('180D Master Plan'!H:H,"<"&EDATE(A22,1)) -> 53 | H22: Quality Engineering | I22: =COUNTIFS('180D Master Plan'!B:B,$H22,'180D Master Plan'!G:G,"<"&DATE(2026,8,1),'180D Master Plan'!H:H,">="&DATE(2026,7,1)) -> 8 | J22: =COUNTIFS('180D Master Plan'!B:B,$H22,'180D Master Plan'!G:G,"<"&DATE(2026,9,1),'180D Master Plan'!H:H,">="&DATE(2026,8,1)) -> 8 | K22: =COUNTIFS('180D Master Plan'!B:B,$H22,'180D Master Plan'!G:G,"<"&DATE(2026,10,1),'180D Master Plan'!H:H,">="&DATE(2026,9,1)) -> 7 | L22: =COUNTIFS('180D Master Plan'!B:B,$H22,'180D Master Plan'!G:G,"<"&DATE(2026,11,1),'180D Master Plan'!H:H,">="&DATE(2026,10,1)) -> 3 | M22: =COUNTIFS('180D Master Plan'!B:B,$H22,'180D Master Plan'!G:G,"<"&DATE(2026,12,1),'180D Master Plan'!H:H,">="&DATE(2026,11,1)) -> 4 | N22: =COUNTIFS('180D Master Plan'!B:B,$H22,'180D Master Plan'!G:G,"<"&DATE(2027,1,1),'180D Master Plan'!H:H,">="&DATE(2026,12,1)) -> 3
A23: 46266 | B23: =COUNTIFS('180D Master Plan'!H:H,">="&A23,'180D Master Plan'!H:H,"<"&EDATE(A23,1)) -> 18 | C23: =COUNTIFS('180D Master Plan'!G:G,">="&A23,'180D Master Plan'!G:G,"<"&EDATE(A23,1)) -> 18 | D23: =COUNTIF('180D Master Plan'!H:H,"<"&EDATE(A23,1)) -> 71 | H23: AIOps Implementation | I23: =COUNTIFS('180D Master Plan'!B:B,$H23,'180D Master Plan'!G:G,"<"&DATE(2026,8,1),'180D Master Plan'!H:H,">="&DATE(2026,7,1)) -> 8 | J23: =COUNTIFS('180D Master Plan'!B:B,$H23,'180D Master Plan'!G:G,"<"&DATE(2026,9,1),'180D Master Plan'!H:H,">="&DATE(2026,8,1)) -> 5 | K23: =COUNTIFS('180D Master Plan'!B:B,$H23,'180D Master Plan'!G:G,"<"&DATE(2026,10,1),'180D Master Plan'!H:H,">="&DATE(2026,9,1)) -> 5 | L23: =COUNTIFS('180D Master Plan'!B:B,$H23,'180D Master Plan'!G:G,"<"&DATE(2026,11,1),'180D Master Plan'!H:H,">="&DATE(2026,10,1)) -> 4 | M23: =COUNTIFS('180D Master Plan'!B:B,$H23,'180D Master Plan'!G:G,"<"&DATE(2026,12,1),'180D Master Plan'!H:H,">="&DATE(2026,11,1)) -> 4 | N23: =COUNTIFS('180D Master Plan'!B:B,$H23,'180D Master Plan'!G:G,"<"&DATE(2027,1,1),'180D Master Plan'!H:H,">="&DATE(2026,12,1)) -> 3
A24: 46296 | B24: =COUNTIFS('180D Master Plan'!H:H,">="&A24,'180D Master Plan'!H:H,"<"&EDATE(A24,1)) -> 8 | C24: =COUNTIFS('180D Master Plan'!G:G,">="&A24,'180D Master Plan'!G:G,"<"&EDATE(A24,1)) -> 10 | D24: =COUNTIF('180D Master Plan'!H:H,"<"&EDATE(A24,1)) -> 79 | H24: CareOps360 | I24: =COUNTIFS('180D Master Plan'!B:B,$H24,'180D Master Plan'!G:G,"<"&DATE(2026,8,1),'180D Master Plan'!H:H,">="&DATE(2026,7,1)) -> 8 | J24: =COUNTIFS('180D Master Plan'!B:B,$H24,'180D Master Plan'!G:G,"<"&DATE(2026,9,1),'180D Master Plan'!H:H,">="&DATE(2026,8,1)) -> 6 | K24: =COUNTIFS('180D Master Plan'!B:B,$H24,'180D Master Plan'!G:G,"<"&DATE(2026,10,1),'180D Master Plan'!H:H,">="&DATE(2026,9,1)) -> 5 | L24: =COUNTIFS('180D Master Plan'!B:B,$H24,'180D Master Plan'!G:G,"<"&DATE(2026,11,1),'180D Master Plan'!H:H,">="&DATE(2026,10,1)) -> 4 | M24: =COUNTIFS('180D Master Plan'!B:B,$H24,'180D Master Plan'!G:G,"<"&DATE(2026,12,1),'180D Master Plan'!H:H,">="&DATE(2026,11,1)) -> 3 | N24: =COUNTIFS('180D Master Plan'!B:B,$H24,'180D Master Plan'!G:G,"<"&DATE(2027,1,1),'180D Master Plan'!H:H,">="&DATE(2026,12,1)) -> 2
A25: 46327 | B25: =COUNTIFS('180D Master Plan'!H:H,">="&A25,'180D Master Plan'!H:H,"<"&EDATE(A25,1)) -> 8 | C25: =COUNTIFS('180D Master Plan'!G:G,">="&A25,'180D Master Plan'!G:G,"<"&EDATE(A25,1)) -> 8 | D25: =COUNTIF('180D Master Plan'!H:H,"<"&EDATE(A25,1)) -> 87 | H25: Agile Product Model | I25: =COUNTIFS('180D Master Plan'!B:B,$H25,'180D Master Plan'!G:G,"<"&DATE(2026,8,1),'180D Master Plan'!H:H,">="&DATE(2026,7,1)) -> 8 | J25: =COUNTIFS('180D Master Plan'!B:B,$H25,'180D Master Plan'!G:G,"<"&DATE(2026,9,1),'180D Master Plan'!H:H,">="&DATE(2026,8,1)) -> 5 | K25: =COUNTIFS('180D Master Plan'!B:B,$H25,'180D Master Plan'!G:G,"<"&DATE(2026,10,1),'180D Master Plan'!H:H,">="&DATE(2026,9,1)) -> 5 | L25: =COUNTIFS('180D Master Plan'!B:B,$H25,'180D Master Plan'!G:G,"<"&DATE(2026,11,1),'180D Master Plan'!H:H,">="&DATE(2026,10,1)) -> 4 | M25: =COUNTIFS('180D Master Plan'!B:B,$H25,'180D Master Plan'!G:G,"<"&DATE(2026,12,1),'180D Master Plan'!H:H,">="&DATE(2026,11,1)) -> 4 | N25: =COUNTIFS('180D Master Plan'!B:B,$H25,'180D Master Plan'!G:G,"<"&DATE(2027,1,1),'180D Master Plan'!H:H,">="&DATE(2026,12,1)) -> 2
A26: 46357 | B26: =COUNTIFS('180D Master Plan'!H:H,">="&A26,'180D Master Plan'!H:H,"<"&EDATE(A26,1)) -> 12 | C26: =COUNTIFS('180D Master Plan'!G:G,">="&A26,'180D Master Plan'!G:G,"<"&EDATE(A26,1)) -> 2 | D26: =COUNTIF('180D Master Plan'!H:H,"<"&EDATE(A26,1)) -> 99
A65: Source / planning assumptions: Plan is derived from the Horizon AMS Reinvention Round 2 Orals deck and assumes a July 1, 2026 transition start. Dates, owners and dependencies should be finalized with Horizon during transition mobilization. Update task Status and % Complete in the Master Plan to refresh dashboard formulas.

Sheet 180D Master Plan
A1: ID | B1: Workstream | C1: Phase | D1: Task / Activity | E1: IBM Owner | F1: Horizon Owner | G1: Start Date | H1: End Date | I1: Duration Days | J1: Dependencies | K1: Deliverable / Milestone | L1: Success Metric | M1: Status | N1: Priority | O1: % Complete | P1: RAG | Q1: Notes
A2: OVE-01 | B2: Overall Transition | C2: 0-30 Foundation | D2: Confirm transition charter, scope, governance cadence and 180-day success criteria | E2: IBM Transformation Lead | F2: Horizon Executive Sponsor | G2: 46204 | H2: 46206 | I2: =H2-G2+1 -> 3 | K2: Signed transition charter | L2: Steering cadence active; 180-day KPIs approved | M2: Not Started | N2: High | O2: 0 | P2: =IF(M2="Completed","Green",IF(TODAY()>H2,"Red",IF(AND(TODAY()+14>H2,O2<0.75),"Amber","Green"))) -> Green
A3: OVE-02 | B3: Overall Transition | C3: 0-30 Foundation | D3: Establish integrated transition command center and daily/weekly operating rhythm | E3: IBM Delivery Lead | F3: Horizon PMO | G3: 46204 | H3: 46208 | I3: =H3-G3+1 -> 5 | J3: TR-01 | K3: Transition command center | L3: Daily standups, weekly operating review, escalation path live | M3: Not Started | N3: High | O3: 0 | P3: =IF(M3="Completed","Green",IF(TODAY()>H3,"Red",IF(AND(TODAY()+14>H3,O3<0.75),"Amber","Green"))) -> Green
A4: OVE-03 | B4: Overall Transition | C4: 0-30 Foundation | D4: Validate in-scope applications, services, SLAs, owners and incumbent knowledge repositories | E4: IBM Transition Manager | F4: Horizon App Owners | G4: 46207 | H4: 46213 | I4: =H4-G4+1 -> 7 | J4: TR-01 | K4: Validated inventory and SLA baseline | L4: 100% critical services mapped | M4: Not Started | N4: High | O4: 0 | P4: =IF(M4="Completed","Green",IF(TODAY()>H4,"Red",IF(AND(TODAY()+14>H4,O4<0.75),"Amber","Green"))) -> Green
A5: OVE-04 | B5: Overall Transition | C5: 0-30 Foundation | D5: Complete access, environment, tooling and onboarding plan for IBM transition resources | E5: IBM Delivery Lead | F5: Horizon Security / ITSM | G5: 46207 | H5: 46216 | I5: =H5-G5+1 -> 10 | J5: TR-01 | K5: Access tracker and onboarding plan | L5: Access SLA agreed; blockers visible | M5: Not Started | N5: High | O5: 0 | P5: =IF(M5="Completed","Green",IF(TODAY()>H5,"Red",IF(AND(TODAY()+14>H5,O5<0.75),"Amber","Green"))) -> Green
A6: OVE-05 | B6: Overall Transition | C6: 0-30 Foundation | D6: Execute knowledge transfer wave 1 for critical applications and operations processes | E6: IBM App Leads | F6: Horizon SMEs | G6: 46211 | H6: 46220 | I6: =H6-G6+1 -> 10 | J6: TR-03;TR-04 | K6: KT wave 1 artifacts | L6: Critical apps have runbooks, support matrix and SME sign-off | M6: Not Started | N6: High | O6: 0 | P6: =IF(M6="Completed","Green",IF(TODAY()>H6,"Red",IF(AND(TODAY()+14>H6,O6<0.75),"Amber","Green"))) -> Green
A7: OVE-06 | B7: Overall Transition | C7: 0-30 Foundation | D7: Baseline current incident, request, change, defect and deployment metrics | E7: IBM Service Delivery Manager | F7: Horizon ITSM Lead | G7: 46215 | H7: 46226 | I7: =H7-G7+1 -> 12 | J7: TR-03 | K7: Operational baseline dashboard | L7: MTTR, ticket volume, backlog aging and SLA baseline captured | M7: Not Started | N7: High | O7: 0 | P7: =IF(M7="Completed","Green",IF(TODAY()>H7,"Red",IF(AND(TODAY()+14>H7,O7<0.75),"Amber","Green"))) -> Green
A8: OVE-07 | B8: Overall Transition | C8: 0-30 Foundation | D8: Map AMS towers to initial product/value-stream POD structure | E8: IBM Product Engineering Lead | F8: Horizon Product Owners | G8: 46218 | H8: 46227 | I8: =H8-G8+1 -> 10 | J8: TR-03 | K8: Initial POD alignment map | L8: Applications mapped to domains/value streams | M8: Not Started | N8: High | O8: 0 | P8: =IF(M8="Completed","Green",IF(TODAY()>H8,"Red",IF(AND(TODAY()+14>H8,O8<0.75),"Amber","Green"))) -> Green
A9: OVE-08 | B9: Overall Transition | C9: 0-30 Foundation | D9: Finalize interim run/support model and hypercare approach for first 60 days | E9: IBM Delivery Lead | F9: Horizon Operations Lead | G9: 46225 | H9: 46234 | I9: =H9-G9+1 -> 10 | J9: TR-02;TR-05 | K9: Run support model | L9: No service disruption; escalation path tested | M9: Not Started | N9: High | O9: 0 | P9: =IF(M9="Completed","Green",IF(TODAY()>H9,"Red",IF(AND(TODAY()+14>H9,O9<0.75),"Amber","Green"))) -> Green
A10: OVE-09 | B10: Overall Transition | C10: 31-60 Production Ready | D10: Stabilize delivery governance, integrated risk log, dependency log and executive reporting | E10: IBM Transformation Office | F10: Horizon PMO | G10: 46234 | H10: 46248 | I10: =H10-G10+1 -> 15 | J10: TR-02;TR-06 | K10: Governance pack | L10: Weekly reporting with risks, dependencies and KPIs | M10: Not Started | N10: High | O10: 0 | P10: =IF(M10="Completed","Green",IF(TODAY()>H10,"Red",IF(AND(TODAY()+14>H10,O10<0.75),"Amber","Green"))) -> Green
A11: OVE-10 | B11: Overall Transition | C11: 31-60 Production Ready | D11: Complete knowledge transfer wave 2 for business-critical and medium-critical applications | E11: IBM App Leads | F11: Horizon SMEs | G11: 46234 | H11: 46253 | I11: =H11-G11+1 -> 20 | J11: TR-05 | K11: KT wave 2 artifacts | L11: >85% KT completion; gaps documented | M11: Not Started | N11: High | O11: 0 | P11: =IF(M11="Completed","Green",IF(TODAY()>H11,"Red",IF(AND(TODAY()+14>H11,O11<0.75),"Amber","Green"))) -> Green
A12: OVE-11 | B12: Overall Transition | C12: 31-60 Production Ready | D12: Transition service delivery accountability to IBM POD/service leads with shadow-to-reverse-shadow plan | E12: IBM Delivery Lead | F12: Horizon Operations Lead | G12: 46243 | H12: 46257 | I12: =H12-G12+1 -> 15 | J12: TR-08;TR-10 | K12: Service transition cutover checklist | L12: POD leads own daily execution | M12: Not Started | N12: High | O12: 0 | P12: =IF(M12="Completed","Green",IF(TODAY()>H12,"Red",IF(AND(TODAY()+14>H12,O12<0.75),"Amber","Green"))) -> Green
A13: OVE-12 | B13: Overall Transition | C13: 31-60 Production Ready | D13: Implement SLA/CSL reporting pack aligned to business KPIs and operational metrics | E13: IBM Service Delivery Manager | F13: Horizon ITSM Lead | G13: 46248 | H13: 46262 | I13: =H13-G13+1 -> 15 | J13: TR-06;TR-09 | K13: SLA/CSL dashboard | L13: Business KPIs and critical service levels visible monthly | M13: Not Started | N13: High | O13: 0 | P13: =IF(M13="Completed","Green",IF(TODAY()>H13,"Red",IF(AND(TODAY()+14>H13,O13<0.75),"Amber","Green"))) -> Green
A14: OVE-13 | B14: Overall Transition | C14: 61-90 Standardize & Integrate | D14: Optimize support model based on 60-day learnings and adjust staffing by product demand | E14: IBM Delivery Lead | F14: Horizon Product Owners | G14: 46264 | H14: 46283 | I14: =H14-G14+1 -> 20 | J14: TR-11;TR-12 | K14: Optimized support model | L14: Backlog and incident queues balanced by domain | M14: Not Started | N14: High | O14: 0 | P14: =IF(M14="Completed","Green",IF(TODAY()>H14,"Red",IF(AND(TODAY()+14>H14,O14<0.75),"Amber","Green"))) -> Green
... A20: OVE-19 | B20: Overall Transition | C20: 91-180 Scale & Optimize | D20: Execute 180-day transition health assessment and transition-to-steady-state acceptance | E20: IBM Delivery Lead | F20: Horizon Executive Sponsor | G20: 46353 | H20: 46382 | I20: =H20-G20+1 -> 30 | J20: TR-16;TR-18 | K20: 180-day acceptance report | L20: Steady-state acceptance and remaining actions signed off | M20: Not Started | N20: High | O20: 0 | P20: =IF(M20="Completed","Green",IF(TODAY()>H20,"Red",IF(AND(TODAY()+14>H20,O20<0.75),"Amber","Green"))) -> Green
A21: QUA-01 | B21: Quality Engineering | C21: 0-30 Foundation | D21: [QE] Mobilize QE transition team, clarify testing scope and confirm QE governance | E21: IBM QE Lead | F21: Horizon QA Lead | G21: 46204 | H21: 46208 | I21: =H21-G21+1 -> 5 | K21: QE mobilization plan | L21: QE governance and owners confirmed | M21: Not Started | N21: High | O21: 0 | P21: =IF(M21="Completed","Green",IF(TODAY()>H21,"Red",IF(AND(TODAY()+14>H21,O21<0.75),"Amber","Green"))) -> Green
A22: QUA-02 | B22: Quality Engineering | C22: 0-30 Foundation | D22: [QE] Assess current test assets, automation coverage, defect leakage and regression cycle health | E22: IBM QE Architect | F22: Horizon QA Lead | G22: 46207 | H22: 46214 | I22: =H22-G22+1 -> 8 | J22: QUA-01 | K22: QE maturity assessment | L22: Automation baseline, test pack gaps and defect trends documented | M22: Not Started | N22: High | O22: 0 | P22: =IF(M22="Completed","Green",IF(TODAY()>H22,"Red",IF(AND(TODAY()+14>H22,O22<0.75),"Amber","Green"))) -> Green
A23: QUA-03 | B23: Quality Engineering | C23: 0-30 Foundation | D23: [QE] Define end-to-end QE strategy: shift-left, BDD/TDD, SIT, UAT support and non-functional testing | E23: IBM QE Lead | F23: Horizon QA Lead | G23: 46211 | H23: 46220 | I23: =H23-G23+1 -> 10 | J23: QUA-02 | K23: QE strategy and playbook | L23: Standardized test lifecycle agreed | M23: Not Started | N23: High | O23: 0 | P23: =IF(M23="Completed","Green",IF(TODAY()>H23,"Red",IF(AND(TODAY()+14>H23,O23<0.75),"Amber","Green"))) -> Green
A24: QUA-04 | B24: Quality Engineering | C24: 0-30 Foundation | D24: [QE] Inventory critical business flows and identify regression pack rationalization opportunities | E24: IBM QE Analyst | F24: Horizon Business SMEs | G24: 46215 | H24: 46226 | I24: =H24-G24+1 -> 12 | J24: QUA-02 | K24: Critical flow catalog | L24: Top flows prioritized by business risk | M24: Not Started | N24: High | O24: 0 | P24: =IF(M24="Completed","Green",IF(TODAY()>H24,"Red",IF(AND(TODAY()+14>H24,O24<0.75),"Amber","Green"))) -> Green
A25: QUA-05 | B25: Quality Engineering | C25: 0-30 Foundation | D25: [QE] Establish requirement-to-test traceability model in Jira/GitHub/toolchain | E25: IBM QE Architect | F25: Horizon Tooling Lead | G25: 46219 | H25: 46233 | I25: =H25-G25+1 -> 15 | J25: QUA-03 | K25: Traceability model | L25: Stories, acceptance criteria and tests linked | M25: Not Started | N25: High | O25: 0 | P25: =IF(M25="Completed","Green",IF(TODAY()>H25,"Red",IF(AND(TODAY()+14>H25,O25<0.75),"Amber","Green"))) -> Green
A26: QUA-06 | B26: Quality Engineering | C26: 0-30 Foundation | D26: [QE] Define test data management strategy including masking, synthetic data and reusable gold copy | E26: IBM TDM Lead | F26: Horizon Data Owner | G26: 46223 | H26: 46237 | I26: =H26-G26+1 -> 15 | J26: QUA-03 | K26: TDM strategy | L26: Data privacy, reuse and refresh strategy approved | M26: Not Started | N26: High | O26: 0 | P26: =IF(M26="Completed","Green",IF(TODAY()>H26,"Red",IF(AND(TODAY()+14>H26,O26<0.75),"Amber","Green"))) -> Green
A27: QUA-07 | B27: Quality Engineering | C27: 0-30 Foundation | D27: [QE] Identify service virtualization/stub needs for APIs, batch, file feeds and external dependencies | E27: IBM QE Architect | F27: Horizon Integration Lead | G27: 46228 | H27: 46237 | I27: =H27-G27+1 -> 10 | J27: QUA-04 | K27: Service virtualization backlog | L27: High-dependency flows prioritized | M27: Not Started | N27: High | O27: 0 | P27: =IF(M27="Completed","Green",IF(TODAY()>H27,"Red",IF(AND(TODAY()+14>H27,O27<0.75),"Amber","Green"))) -> Green
A28: QUA-08 | B28: Quality Engineering | C28: 31-60 Production Ready | D28: [QE] Stand up QE CoE operating model, standards, templates and metrics dashboard | E28: IBM QE Lead | F28: Horizon QA Lead | G28: 46234 | H28: 46248 | I28: =H28-G28+1 -> 15 | J28: QUA-01;QUA-03 | K28: QE CoE model | L28: Common metrics and templates used by PODs | M28: Not Started | N28: High | O28: 0 | P28: =IF(M28="Completed","Green",IF(TODAY()>H28,"Red",IF(AND(TODAY()+14>H28,O28<0.75),"Amber","Green"))) -> Green
A29: QUA-09 | B29: Quality Engineering | C29: 31-60 Production Ready | D29: [QE] Rationalize existing regression suite and remove redundant / low-value tests | E29: IBM QE Factory Lead | F29: Horizon QA Lead | G29: 46238 | H29: 46257 | I29: =H29-G29+1 -> 20 | J29: QUA-04 | K29: Optimized regression pack | L29: Regression pack reduced without coverage loss | M29: Not Started | N29: High | O29: 0 | P29: =IF(M29="Completed","Green",IF(TODAY()>H29,"Red",IF(AND(TODAY()+14>H29,O29<0.75),"Amber","Green"))) -> Green
A30: QUA-10 | B30: Quality Engineering | C30: 31-60 Production Ready | D30: [QE] Implement AI-assisted test case generation pilot from requirements/user stories | E30: IBM QE Automation Lead | F30: Horizon Product Owners | G30: 46243 | H30: 46262 | I30: =H30-G30+1 -> 20 | J30: QUA-05 | K30: AI test generation pilot | L30: Req-to-test productivity baseline captured | M30: Not Started | N30: High | O30: 0 | P30: =IF(M30="Completed","Green",IF(TODAY()>H30,"Red",IF(AND(TODAY()+14>H30,O30<0.75),"Amber","Green"))) -> Green
A31: QUA-11 | B31: Quality Engineering | C31: 31-60 Production Ready | D31: [QE] Build automation framework enhancements for API, UI, component and batch regression | E31: IBM QE Automation Lead | F31: Horizon DevOps Lead | G31: 46248 | H31: 46267 | I31: =H31-G31+1 -> 20 | J31: QUA-07;QUA-09 | K31: Automation framework update | L31: Reusable framework supports CI/CD integration | M31: Not Started | N31: High | O31: 0 | P31: =IF(M31="Completed","Green",IF(TODAY()>H31,"Red",IF(AND(TODAY()+14>H31,O31<0.75),"Amber","Green"))) -> Green
A32: QUA-12 | B32: Quality Engineering | C32: 31-60 Production Ready | D32: [QE] Create first automated smoke and regression packs for pilot product POD | E32: IBM QE Automation Lead | F32: Horizon QA Lead | G32: 46258 | H32: 46272 | I32: =H32-G32+1 -> 15 | J32: QUA-10;QUA-11 | K32: Pilot automated pack | L32: Smoke tests executable in pipeline | M32: Not Started | N32: High | O32: 0 | P32: =IF(M32="Completed","Green",IF(TODAY()>H32,"Red",IF(AND(TODAY()+14>H32,O32<0.75),"Amber","Green"))) -> Green
A33: QUA-13 | B33: Quality Engineering | C33: 61-90 Standardize & Integrate | D33: [QE] Integrate automated tests into CI/CD gates for pilot cloud applications | E33: IBM DevSecOps Lead | F33: Horizon DevOps Lead | G33: 46264 | H33: 46283 | I33: =H33-G33+1 -> 20 | J33: QUA-11;QUA-12 | K33: CI/CD quality gates | L33: Automated tests triggered on builds/deployments | M33: Not Started | N33: High | O33: 0 | P33: =IF(M33="Completed","Green",IF(TODAY()>H33,"Red",IF(AND(TODAY()+14>H33,O33<0.75),"Amber","Green"))) -> Green
... A41: QUA-21 | B41: Quality Engineering | C41: 91-180 Scale & Optimize | D41: [QE] Conduct 180-day QE maturity reassessment and finalize scale roadmap | E41: IBM QE Lead | F41: Horizon QA Lead | G41: 46353 | H41: 46382 | I41: =H41-G41+1 -> 30 | J41: QUA-18;QUA-20 | K41: QE scale roadmap | L41: Maturity improvement and next-wave roadmap approved | M41: Not Started | N41: High | O41: 0 | P41: =IF(M41="Completed","Green",IF(TODAY()>H41,"Red",IF(AND(TODAY()+14>H41,O41<0.75),"Amber","Green"))) -> Green
A42: AIO-01 | B42: AIOps Implementation | C42: 0-30 Foundation | D42: Confirm AIOps scope, target architecture, ARB/security path and first 5 AWS-hosted applications | E42: IBM AIOps Program Manager | F42: Horizon ARB / Security | G42: 46204 | H42: 46208 | I42: =H42-G42+1 -> 5 | K42: AIOps implementation charter | L42: Scope and approval path agreed | M42: Not Started | N42: High | O42: 0 | P42: =IF(M42="Completed","Green",IF(TODAY()>H42,"Red",IF(AND(TODAY()+14>H42,O42<0.75),"Amber","Green"))) -> Green
A43: AIO-02 | B43: AIOps Implementation | C43: 0-30 Foundation | D43: Provision AIOps dev/test environments and connectivity pattern for Horizon ecosystem | E43: IBM AIOps Architect | F43: Horizon Infrastructure Lead | G43: 46207 | H43: 46216 | I43: =H43-G43+1 -> 10 | J43: AIO-01 | K43: AIOps environment ready | L43: Environment provisioned; connectivity tested | M43: Not Started | N43: High | O43: 0 | P43: =IF(M43="Completed","Green",IF(TODAY()>H43,"Red",IF(AND(TODAY()+14>H43,O43<0.75),"Amber","Green"))) -> Green
A44: AIO-03 | B44: AIOps Implementation | C44: 0-30 Foundation | D44: Ingest historical ITSM ticket data and establish ticket taxonomy, resolution patterns and knowledge sources | E44: IBM AIOps Data Lead | F44: Horizon ITSM Lead | G44: 46211 | H44: 46222 | I44: =H44-G44+1 -> 12 | J44: AIO-01 | K44: Historical data ingestion | L44: Ticket data loaded and normalized | M44: Not Started | N44: High | O44: 0 | P44: =IF(M44="Completed","Green",IF(TODAY()>H44,"Red",IF(AND(TODAY()+14>H44,O44<0.75),"Amber","Green"))) -> Green
A45: AIO-04 | B45: AIOps Implementation | C45: 0-30 Foundation | D45: Integrate ServiceNow/ClearQuest transition considerations and define ITSM workflow interfaces | E45: IBM ITSM Integration Lead | F45: Horizon ITSM Lead | G45: 46215 | H45: 46226 | I45: =H45-G45+1 -> 12 | J45: AIO-01;AIO-03 | K45: ITSM integration design | L45: Workflow and data contracts agreed | M45: Not Started | N45: High | O45: 0 | P45: =IF(M45="Completed","Green",IF(TODAY()>H45,"Red",IF(AND(TODAY()+14>H45,O45<0.75),"Amber","Green"))) -> Green
A46: AIO-05 | B46: AIOps Implementation | C46: 0-30 Foundation | D46: Connect priority monitoring sources and logs for first cloud-app pilot set | E46: IBM Observability Lead | F46: Horizon Monitoring Lead | G46: 46218 | H46: 46232 | I46: =H46-G46+1 -> 15 | J46: AIO-02 | K46: Pilot observability integrations | L46: Initial alerts/logs flowing | M46: Not Started | N46: High | O46: 0 | P46: =IF(M46="Completed","Green",IF(TODAY()>H46,"Red",IF(AND(TODAY()+14>H46,O46<0.75),"Amber","Green"))) -> Green
A47: AIO-06 | B47: AIOps Implementation | C47: 0-30 Foundation | D47: Configure default AIOps dashboards for operations, leadership and product teams | E47: IBM AIOps Lead | F47: Horizon Operations Lead | G47: 46223 | H47: 46232 | I47: =H47-G47+1 -> 10 | J47: AIO-03;AIO-05 | K47: Default dashboards | L47: Operational visibility available | M47: Not Started | N47: High | O47: 0 | P47: =IF(M47="Completed","Green",IF(TODAY()>H47,"Red",IF(AND(TODAY()+14>H47,O47<0.75),"Amber","Green"))) -> Green
A48: AIO-07 | B48: AIOps Implementation | C48: 0-30 Foundation | D48: Train initial models for alert grouping, noise reduction and auto-triage | E48: IBM AIOps Data Scientist | F48: Horizon Operations SMEs | G48: 46228 | H48: 46242 | I48: =H48-G48+1 -> 15 | J48: AIO-03;AIO-05 | K48: Model training baseline | L48: Initial auto-triage accuracy baseline | M48: Not Started | N48: High | O48: 0 | P48: =IF(M48="Completed","Green",IF(TODAY()>H48,"Red",IF(AND(TODAY()+14>H48,O48<0.75),"Amber","Green"))) -> Green
A49: AIO-08 | B49: AIOps Implementation | C49: 31-60 Production Ready | D49: Validate auto-triage for first 5 AWS-hosted applications with human-in-the-loop governance | E49: IBM AIOps Lead | F49: Horizon Operations Lead | G49: 46234 | H49: 46253 | I49: =H49-G49+1 -> 20 | J49: AIO-05;AIO-07 | K49: Auto-triage pilot | L49: Pilot apps validated for triage recommendations | M49: Not Started | N49: High | O49: 0 | P49: =IF(M49="Completed","Green",IF(TODAY()>H49,"Red",IF(AND(TODAY()+14>H49,O49<0.75),"Amber","Green"))) -> Green
A50: AIO-09 | B50: AIOps Implementation | C50: 31-60 Production Ready | D50: Curate knowledge corpus from runbooks, SOPs, RCA and incident resolutions | E50: IBM Knowledge Manager | F50: Horizon SMEs | G50: 46238 | H50: 46257 | I50: =H50-G50+1 -> 20 | J50: AIO-03;AIO-07 | K50: Knowledge corpus | L50: Runbooks and resolutions searchable by agents | M50: Not Started | N50: High | O50: 0 | P50: =IF(M50="Completed","Green",IF(TODAY()>H50,"Red",IF(AND(TODAY()+14>H50,O50<0.75),"Amber","Green"))) -> Green
A51: AIO-10 | B51: AIOps Implementation | C51: 31-60 Production Ready | D51: Define controlled auto-remediation candidate backlog and risk guardrails | E51: IBM SRE Lead | F51: Horizon Risk / Security | G51: 46248 | H51: 46262 | I51: =H51-G51+1 -> 15 | J51: AIO-08;AIO-09 | K51: Runbook automation backlog | L51: Low-risk candidates approved | M51: Not Started | N51: High | O51: 0 | P51: =IF(M51="Completed","Green",IF(TODAY()>H51,"Red",IF(AND(TODAY()+14>H51,O51<0.75),"Amber","Green"))) -> Green
A52: AIO-11 | B52: AIOps Implementation | C52: 61-90 Standardize & Integrate | D52: Standardize log, event and alert normalization across cloud applications | E52: IBM Observability Lead | F52: Horizon Monitoring Lead | G52: 46264 | H52: 46283 | I52: =H52-G52+1 -> 20 | J52: AIO-08;AIO-09 | K52: Standardized ingestion rules | L52: Consistent alert taxonomy across cloud apps | M52: Not Started | N52: High | O52: 0 | P52: =IF(M52="Completed","Green",IF(TODAY()>H52,"Red",IF(AND(TODAY()+14>H52,O52<0.75),"Amber","Green"))) -> Green
...

Sheet Overall Transition
A1: ID | B1: Workstream | C1: Phase | D1: Task / Activity | E1: IBM Owner | F1: Horizon Owner | G1: Start Date | H1: End Date | I1: Duration Days | J1: Dependencies | K1: Deliverable / Milestone | L1: Success Metric | M1: Status | N1: Priority | O1: % Complete | P1: RAG | Q1: Notes
A2: OVE-01 | B2: Overall Transition | C2: 0-30 Foundation | D2: Confirm transition charter, scope, governance cadence and 180-day success criteria | E2: IBM Transformation Lead | F2: Horizon Executive Sponsor | G2: 46204 | H2: 46206 | I2: =H2-G2+1 -> 3 | K2: Signed transition charter | L2: Steering cadence active; 180-day KPIs approved | M2: Not Started | N2: High | O2: 0 | P2: =IF(M2="Completed","Green",IF(TODAY()>H2,"Red",IF(AND(TODAY()+14>H2,O2<0.75),"Amber","Green"))) -> Green
A3: OVE-02 | B3: Overall Transition | C3: 0-30 Foundation | D3: Establish integrated transition command center and daily/weekly operating rhythm | E3: IBM Delivery Lead | F3: Horizon PMO | G3: 46204 | H3: 46208 | I3: =H3-G3+1 -> 5 | J3: TR-01 | K3: Transition command center | L3: Daily standups, weekly operating review, escalation path live | M3: Not Started | N3: High | O3: 0 | P3: =IF(M3="Completed","Green",IF(TODAY()>H3,"Red",IF(AND(TODAY()+14>H3,O3<0.75),"Amber","Green"))) -> Green
A4: OVE-03 | B4: Overall Transition | C4: 0-30 Foundation | D4: Validate in-scope applications, services, SLAs, owners and incumbent knowledge repositories | E4: IBM Transition Manager | F4: Horizon App Owners | G4: 46207 | H4: 46213 | I4: =H4-G4+1 -> 7 | J4: TR-01 | K4: Validated inventory and SLA baseline | L4: 100% critical services mapped | M4: Not Started | N4: High | O4: 0 | P4: =IF(M4="Completed","Green",IF(TODAY()>H4,"Red",IF(AND(TODAY()+14>H4,O4<0.75),"Amber","Green"))) -> Green
A5: OVE-04 | B5: Overall Transition | C5: 0-30 Foundation | D5: Complete access, environment, tooling and onboarding plan for IBM transition resources | E5: IBM Delivery Lead | F5: Horizon Security / ITSM | G5: 46207 | H5: 46216 | I5: =H5-G5+1 -> 10 | J5: TR-01 | K5: Access tracker and onboarding plan | L5: Access SLA agreed; blockers visible | M5: Not Started | N5: High | O5: 0 | P5: =IF(M5="Completed","Green",IF(TODAY()>H5,"Red",IF(AND(TODAY()+14>H5,O5<0.75),"Amber","Green"))) -> Green
A6: OVE-05 | B6: Overall Transition | C6: 0-30 Foundation | D6: Execute knowledge transfer wave 1 for critical applications and operations processes | E6: IBM App Leads | F6: Horizon SMEs | G6: 46211 | H6: 46220 | I6: =H6-G6+1 -> 10 | J6: TR-03;TR-04 | K6: KT wave 1 artifacts | L6: Critical apps have runbooks, support matrix and SME sign-off | M6: Not Started | N6: High | O6: 0 | P6: =IF(M6="Completed","Green",IF(TODAY()>H6,"Red",IF(AND(TODAY()+14>H6,O6<0.75),"Amber","Green"))) -> Green
A7: OVE-06 | B7: Overall Transition | C7: 0-30 Foundation | D7: Baseline current incident, request, change, defect and deployment metrics | E7: IBM Service Delivery Manager | F7: Horizon ITSM Lead | G7: 46215 | H7: 46226 | I7: =H7-G7+1 -> 12 | J7: TR-03 | K7: Operational baseline dashboard | L7: MTTR, ticket volume, backlog aging and SLA baseline captured | M7: Not Started | N7: High | O7: 0 | P7: =IF(M7="Completed","Green",IF(TODAY()>H7,"Red",IF(AND(TODAY()+14>H7,O7<0.75),"Amber","Green"))) -> Green
A8: OVE-07 | B8: Overall Transition | C8: 0-30 Foundation | D8: Map AMS towers to initial product/value-stream POD structure | E8: IBM Product Engineering Lead | F8: Horizon Product Owners | G8: 46218 | H8: 46227 | I8: =H8-G8+1 -> 10 | J8: TR-03 | K8: Initial POD alignment map | L8: Applications mapped to domains/value streams | M8: Not Started | N8: High | O8: 0 | P8: =IF(M8="Completed","Green",IF(TODAY()>H8,"Red",IF(AND(TODAY()+14>H8,O8<0.75),"Amber","Green"))) -> Green
A9: OVE-08 | B9: Overall Transition | C9: 0-30 Foundation | D9: Finalize interim run/support model and hypercare approach for first 60 days | E9: IBM Delivery Lead | F9: Horizon Operations Lead | G9: 46225 | H9: 46234 | I9: =H9-G9+1 -> 10 | J9: TR-02;TR-05 | K9: Run support model | L9: No service disruption; escalation path tested | M9: Not Started | N9: High | O9: 0 | P9: =IF(M9="Completed","Green",IF(TODAY()>H9,"Red",IF(AND(TODAY()+14>H9,O9<0.75),"Amber","Green"))) -> Green
A10: OVE-09 | B10: Overall Transition | C10: 31-60 Production Ready | D10: Stabilize delivery governance, integrated risk log, dependency log and executive reporting | E10: IBM Transformation Office | F10: Horizon PMO | G10: 46234 | H10: 46248 | I10: =H10-G10+1 -> 15 | J10: TR-02;TR-06 | K10: Governance pack | L10: Weekly reporting with risks, dependencies and KPIs | M10: Not Started | N10: High | O10: 0 | P10: =IF(M10="Completed","Green",IF(TODAY()>H10,"Red",IF(AND(TODAY()+14>H10,O10<0.75),"Amber","Green"))) -> Green
A11: OVE-10 | B11: Overall Transition | C11: 31-60 Production Ready | D11: Complete knowledge transfer wave 2 for business-critical and medium-critical applications | E11: IBM App Leads | F11: Horizon SMEs | G11: 46234 | H11: 46253 | I11: =H11-G11+1 -> 20 | J11: TR-05 | K11: KT wave 2 artifacts | L11: >85% KT completion; gaps documented | M11: Not Started | N11: High | O11: 0 | P11: =IF(M11="Completed","Green",IF(TODAY()>H11,"Red",IF(AND(TODAY()+14>H11,O11<0.75),"Amber","Green"))) -> Green
A12: OVE-11 | B12: Overall Transition | C12: 31-60 Production Ready | D12: Transition service delivery accountability to IBM POD/service leads with shadow-to-reverse-shadow plan | E12: IBM Delivery Lead | F12: Horizon Operations Lead | G12: 46243 | H12: 46257 | I12: =H12-G12+1 -> 15 | J12: TR-08;TR-10 | K12: Service transition cutover checklist | L12: POD leads own daily execution | M12: Not Started | N12: High | O12: 0 | P12: =IF(M12="Completed","Green",IF(TODAY()>H12,"Red",IF(AND(TODAY()+14>H12,O12<0.75),"Amber","Green"))) -> Green
A13: OVE-12 | B13: Overall Transition | C13: 31-60 Production Ready | D13: Implement SLA/CSL reporting pack aligned to business KPIs and operational metrics | E13: IBM Service Delivery Manager | F13: Horizon ITSM Lead | G13: 46248 | H13: 46262 | I13: =H13-G13+1 -> 15 | J13: TR-06;TR-09 | K13: SLA/CSL dashboard | L13: Business KPIs and critical service levels visible monthly | M13: Not Started | N13: High | O13: 0 | P13: =IF(M13="Completed","Green",IF(TODAY()>H13,"Red",IF(AND(TODAY()+14>H13,O13<0.75),"Amber","Green"))) -> Green
A14: OVE-13 | B14: Overall Transition | C14: 61-90 Standardize & Integrate | D14: Optimize support model based on 60-day learnings and adjust staffing by product demand | E14: IBM Delivery Lead | F14: Horizon Product Owners | G14: 46264 | H14: 46283 | I14: =H14-G14+1 -> 20 | J14: TR-11;TR-12 | K14: Optimized support model | L14: Backlog and incident queues balanced by domain | M14: Not Started | N14: High | O14: 0 | P14: =IF(M14="Completed","Green",IF(TODAY()>H14,"Red",IF(AND(TODAY()+14>H14,O14<0.75),"Amber","Green"))) -> Green
... A20: OVE-19 | B20: Overall Transition | C20: 91-180 Scale & Optimize | D20: Execute 180-day transition health assessment and transition-to-steady-state acceptance | E20: IBM Delivery Lead | F20: Horizon Executive Sponsor | G20: 46353 | H20: 46382 | I20: =H20-G20+1 -> 30 | J20: TR-16;TR-18 | K20: 180-day acceptance report | L20: Steady-state acceptance and remaining actions signed off | M20: Not Started | N20: High | O20: 0 | P20: =IF(M20="Completed","Green",IF(TODAY()>H20,"Red",IF(AND(TODAY()+14>H20,O20<0.75),"Amber","Green"))) -> Green

Sheet Quality Engineering
A1: ID | B1: Workstream | C1: Phase | D1: Task / Activity | E1: IBM Owner | F1: Horizon Owner | G1: Start Date | H1: End Date | I1: Duration Days | J1: Dependencies | K1: Deliverable / Milestone | L1: Success Metric | M1: Status | N1: Priority | O1: % Complete | P1: RAG | Q1: Notes
A2: QUA-01 | B2: Quality Engineering | C2: 0-30 Foundation | D2: [QE] Mobilize QE transition team, clarify testing scope and confirm QE governance | E2: IBM QE Lead | F2: Horizon QA Lead | G2: 46204 | H2: 46208 | I2: =H2-G2+1 -> 5 | K2: QE mobilization plan | L2: QE governance and owners confirmed | M2: Not Started | N2: High | O2: 0 | P2: =IF(M2="Completed","Green",IF(TODAY()>H2,"Red",IF(AND(TODAY()+14>H2,O2<0.75),"Amber","Green"))) -> Green
A3: QUA-02 | B3: Quality Engineering | C3: 0-30 Foundation | D3: [QE] Assess current test assets, automation coverage, defect leakage and regression cycle health | E3: IBM QE Architect | F3: Horizon QA Lead | G3: 46207 | H3: 46214 | I3: =H3-G3+1 -> 8 | J3: QUA-01 | K3: QE maturity assessment | L3: Automation baseline, test pack gaps and defect trends documented | M3: Not Started | N3: High | O3: 0 | P3: =IF(M3="Completed","Green",IF(TODAY()>H3,"Red",IF(AND(TODAY()+14>H3,O3<0.75),"Amber","Green"))) -> Green
A4: QUA-03 | B4: Quality Engineering | C4: 0-30 Foundation | D4: [QE] Define end-to-end QE strategy: shift-left, BDD/TDD, SIT, UAT support and non-functional testing | E4: IBM QE Lead | F4: Horizon QA Lead | G4: 46211 | H4: 46220 | I4: =H4-G4+1 -> 10 | J4: QUA-02 | K4: QE strategy and playbook | L4: Standardized test lifecycle agreed | M4: Not Started | N4: High | O4: 0 | P4: =IF(M4="Completed","Green",IF(TODAY()>H4,"Red",IF(AND(TODAY()+14>H4,O4<0.75),"Amber","Green"))) -> Green
A5: QUA-04 | B5: Quality Engineering | C5: 0-30 Foundation | D5: [QE] Inventory critical business flows and identify regression pack rationalization opportunities | E5: IBM QE Analyst | F5: Horizon Business SMEs | G5: 46215 | H5: 46226 | I5: =H5-G5+1 -> 12 | J5: QUA-02 | K5: Critical flow catalog | L5: Top flows prioritized by business risk | M5: Not Started | N5: High | O5: 0 | P5: =IF(M5="Completed","Green",IF(TODAY()>H5,"Red",IF(AND(TODAY()+14>H5,O5<0.75),"Amber","Green"))) -> Green
A6: QUA-05 | B6: Quality Engineering | C6: 0-30 Foundation | D6: [QE] Establish requirement-to-test traceability model in Jira/GitHub/toolchain | E6: IBM QE Architect | F6: Horizon Tooling Lead | G6: 46219 | H6: 46233 | I6: =H6-G6+1 -> 15 | J6: QUA-03 | K6: Traceability model | L6: Stories, acceptance criteria and tests linked | M6: Not Started | N6: High | O6: 0 | P6: =IF(M6="Completed","Green",IF(TODAY()>H6,"Red",IF(AND(TODAY()+14>H6,O6<0.75),"Amber","Green"))) -> Green
A7: QUA-06 | B7: Quality Engineering | C7: 0-30 Foundation | D7: [QE] Define test data management strategy including masking, synthetic data and reusable gold copy | E7: IBM TDM Lead | F7: Horizon Data Owner | G7: 46223 | H7: 46237 | I7: =H7-G7+1 -> 15 | J7: QUA-03 | K7: TDM strategy | L7: Data privacy, reuse and refresh strategy approved | M7: Not Started | N7: High | O7: 0 | P7: =IF(M7="Completed","Green",IF(TODAY()>H7,"Red",IF(AND(TODAY()+14>H7,O7<0.75),"Amber","Green"))) -> Green
A8: QUA-07 | B8: Quality Engineering | C8: 0-30 Foundation | D8: [QE] Identify service virtualization/stub needs for APIs, batch, file feeds and external dependencies | E8: IBM QE Architect | F8: Horizon Integration Lead | G8: 46228 | H8: 46237 | I8: =H8-G8+1 -> 10 | J8: QUA-04 | K8: Service virtualization backlog | L8: High-dependency flows prioritized | M8: Not Started | N8: High | O8: 0 | P8: =IF(M8="Completed","Green",IF(TODAY()>H8,"Red",IF(AND(TODAY()+14>H8,O8<0.75),"Amber","Green"))) -> Green
A9: QUA-08 | B9: Quality Engineering | C9: 31-60 Production Ready | D9: [QE] Stand up QE CoE operating model, standards, templates and metrics dashboard | E9: IBM QE Lead | F9: Horizon QA Lead | G9: 46234 | H9: 46248 | I9: =H9-G9+1 -> 15 | J9: QUA-01;QUA-03 | K9: QE CoE model | L9: Common metrics and templates used by PODs | M9: Not Started | N9: High | O9: 0 | P9: =IF(M9="Completed","Green",IF(TODAY()>H9,"Red",IF(AND(TODAY()+14>H9,O9<0.75),"Amber","Green"))) -> Green
A10: QUA-09 | B10: Quality Engineering | C10: 31-60 Production Ready | D10: [QE] Rationalize existing regression suite and remove redundant / low-value tests | E10: IBM QE Factory Lead | F10: Horizon QA Lead | G10: 46238 | H10: 46257 | I10: =H10-G10+1 -> 20 | J10: QUA-04 | K10: Optimized regression pack | L10: Regression pack reduced without coverage loss | M10: Not Started | N10: High | O10: 0 | P10: =IF(M10="Completed","Green",IF(TODAY()>H10,"Red",IF(AND(TODAY()+14>H10,O10<0.75),"Amber","Green"))) -> Green
A11: QUA-10 | B11: Quality Engineering | C11: 31-60 Production Ready | D11: [QE] Implement AI-assisted test case generation pilot from requirements/user stories | E11: IBM QE Automation Lead | F11: Horizon Product Owners | G11: 46243 | H11: 46262 | I11: =H11-G11+1 -> 20 | J11: QUA-05 | K11: AI test generation pilot | L11: Req-to-test productivity baseline captured | M11: Not Started | N11: High | O11: 0 | P11: =IF(M11="Completed","Green",IF(TODAY()>H11,"Red",IF(AND(TODAY()+14>H11,O11<0.75),"Amber","Green"))) -> Green
A12: QUA-11 | B12: Quality Engineering | C12: 31-60 Production Ready | D12: [QE] Build automation framework enhancements for API, UI, component and batch regression | E12: IBM QE Automation Lead | F12: Horizon DevOps Lead | G12: 46248 | H12: 46267 | I12: =H12-G12+1 -> 20 | J12: QUA-07;QUA-09 | K12: Automation framework update | L12: Reusable framework supports CI/CD integration | M12: Not Started | N12: High | O12: 0 | P12: =IF(M12="Completed","Green",IF(TODAY()>H12,"Red",IF(AND(TODAY()+14>H12,O12<0.75),"Amber","Green"))) -> Green
A13: QUA-12 | B13: Quality Engineering | C13: 31-60 Production Ready | D13: [QE] Create first automated smoke and regression packs for pilot product POD | E13: IBM QE Automation Lead | F13: Horizon QA Lead | G13: 46258 | H13: 46272 | I13: =H13-G13+1 -> 15 | J13: QUA-10;QUA-11 | K13: Pilot automated pack | L13: Smoke tests executable in pipeline | M13: Not Started | N13: High | O13: 0 | P13: =IF(M13="Completed","Green",IF(TODAY()>H13,"Red",IF(AND(TODAY()+14>H13,O13<0.75),"Amber","Green"))) -> Green
A14: QUA-13 | B14: Quality Engineering | C14: 61-90 Standardize & Integrate | D14: [QE] Integrate automated tests into CI/CD gates for pilot cloud applications | E14: IBM DevSecOps Lead | F14: Horizon DevOps Lead | G14: 46264 | H14: 46283 | I14: =H14-G14+1 -> 20 | J14: QUA-11;QUA-12 | K14: CI/CD quality gates | L14: Automated tests triggered on builds/deployments | M14: Not Started | N14: High | O14: 0 | P14: =IF(M14="Completed","Green",IF(TODAY()>H14,"Red",IF(AND(TODAY()+14>H14,O14<0.75),"Amber","Green"))) -> Green
... A22: QUA-21 | B22: Quality Engineering | C22: 91-180 Scale & Optimize | D22: [QE] Conduct 180-day QE maturity reassessment and finalize scale roadmap | E22: IBM QE Lead | F22: Horizon QA Lead | G22: 46353 | H22: 46382 | I22: =H22-G22+1 -> 30 | J22: QUA-18;QUA-20 | K22: QE scale roadmap | L22: Maturity improvement and next-wave roadmap approved | M22: Not Started | N22: High | O22: 0 | P22: =IF(M22="Completed","Green",IF(TODAY()>H22,"Red",IF(AND(TODAY()+14>H22,O22<0.75),"Amber","Green"))) -> Green

Sheet AIOps Implementation
A1: ID | B1: Workstream | C1: Phase | D1: Task / Activity | E1: IBM Owner | F1: Horizon Owner | G1: Start Date | H1: End Date | I1: Duration Days | J1: Dependencies | K1: Deliverable / Milestone | L1: Success Metric | M1: Status | N1: Priority | O1: % Complete | P1: RAG | Q1: Notes
A2: AIO-01 | B2: AIOps Implementation | C2: 0-30 Foundation | D2: Confirm AIOps scope, target architecture, ARB/security path and first 5 AWS-hosted applications | E2: IBM AIOps Program Manager | F2: Horizon ARB / Security | G2: 46204 | H2: 46208 | I2: =H2-G2+1 -> 5 | K2: AIOps implementation charter | L2: Scope and approval path agreed | M2: Not Started | N2: High | O2: 0 | P2: =IF(M2="Completed","Green",IF(TODAY()>H2,"Red",IF(AND(TODAY()+14>H2,O2<0.75),"Amber","Green"))) -> Green
A3: AIO-02 | B3: AIOps Implementation | C3: 0-30 Foundation | D3: Provision AIOps dev/test environments and connectivity pattern for Horizon ecosystem | E3: IBM AIOps Architect | F3: Horizon Infrastructure Lead | G3: 46207 | H3: 46216 | I3: =H3-G3+1 -> 10 | J3: AIO-01 | K3: AIOps environment ready | L3: Environment provisioned; connectivity tested | M3: Not Started | N3: High | O3: 0 | P3: =IF(M3="Completed","Green",IF(TODAY()>H3,"Red",IF(AND(TODAY()+14>H3,O3<0.75),"Amber","Green"))) -> Green
A4: AIO-03 | B4: AIOps Implementation | C4: 0-30 Foundation | D4: Ingest historical ITSM ticket data and establish ticket taxonomy, resolution patterns and knowledge sources | E4: IBM AIOps Data Lead | F4: Horizon ITSM Lead | G4: 46211 | H4: 46222 | I4: =H4-G4+1 -> 12 | J4: AIO-01 | K4: Historical data ingestion | L4: Ticket data loaded and normalized | M4: Not Started | N4: High | O4: 0 | P4: =IF(M4="Completed","Green",IF(TODAY()>H4,"Red",IF(AND(TODAY()+14>H4,O4<0.75),"Amber","Green"))) -> Green
A5: AIO-04 | B5: AIOps Implementation | C5: 0-30 Foundation | D5: Integrate ServiceNow/ClearQuest transition considerations and define ITSM workflow interfaces | E5: IBM ITSM Integration Lead | F5: Horizon ITSM Lead | G5: 46215 | H5: 46226 | I5: =H5-G5+1 -> 12 | J5: AIO-01;AIO-03 | K5: ITSM integration design | L5: Workflow and data contracts agreed | M5: Not Started | N5: High | O5: 0 | P5: =IF(M5="Completed","Green",IF(TODAY()>H5,"Red",IF(AND(TODAY()+14>H5,O5<0.75),"Amber","Green"))) -> Green
A6: AIO-05 | B6: AIOps Implementation | C6: 0-30 Foundation | D6: Connect priority monitoring sources and logs for first cloud-app pilot set | E6: IBM Observability Lead | F6: Horizon Monitoring Lead | G6: 46218 | H6: 46232 | I6: =H6-G6+1 -> 15 | J6: AIO-02 | K6: Pilot observability integrations | L6: Initial alerts/logs flowing | M6: Not Started | N6: High | O6: 0 | P6: =IF(M6="Completed","Green",IF(TODAY()>H6,"Red",IF(AND(TODAY()+14>H6,O6<0.75),"Amber","Green"))) -> Green
A7: AIO-06 | B7: AIOps Implementation | C7: 0-30 Foundation | D7: Configure default AIOps dashboards for operations, leadership and product teams | E7: IBM AIOps Lead | F7: Horizon Operations Lead | G7: 46223 | H7: 46232 | I7: =H7-G7+1 -> 10 | J7: AIO-03;AIO-05 | K7: Default dashboards | L7: Operational visibility available | M7: Not Started | N7: High | O7: 0 | P7: =IF(M7="Completed","Green",IF(TODAY()>H7,"Red",IF(AND(TODAY()+14>H7,O7<0.75),"Amber","Green"))) -> Green
A8: AIO-07 | B8: AIOps Implementation | C8: 0-30 Foundation | D8: Train initial models for alert grouping, noise reduction and auto-triage | E8: IBM AIOps Data Scientist | F8: Horizon Operations SMEs | G8: 46228 | H8: 46242 | I8: =H8-G8+1 -> 15 | J8: AIO-03;AIO-05 | K8: Model training baseline | L8: Initial auto-triage accuracy baseline | M8: Not Started | N8: High | O8: 0 | P8: =IF(M8="Completed","Green",IF(TODAY()>H8,"Red",IF(AND(TODAY()+14>H8,O8<0.75),"Amber","Green"))) -> Green
A9: AIO-08 | B9: AIOps Implementation | C9: 31-60 Production Ready | D9: Validate auto-triage for first 5 AWS-hosted applications with human-in-the-loop governance | E9: IBM AIOps Lead | F9: Horizon Operations Lead | G9: 46234 | H9: 46253 | I9: =H9-G9+1 -> 20 | J9: AIO-05;AIO-07 | K9: Auto-triage pilot | L9: Pilot apps validated for triage recommendations | M9: Not Started | N9: High | O9: 0 | P9: =IF(M9="Completed","Green",IF(TODAY()>H9,"Red",IF(AND(TODAY()+14>H9,O9<0.75),"Amber","Green"))) -> Green
A10: AIO-09 | B10: AIOps Implementation | C10: 31-60 Production Ready | D10: Curate knowledge corpus from runbooks, SOPs, RCA and incident resolutions | E10: IBM Knowledge Manager | F10: Horizon SMEs | G10: 46238 | H10: 46257 | I10: =H10-G10+1 -> 20 | J10: AIO-03;AIO-07 | K10: Knowledge corpus | L10: Runbooks and resolutions searchable by agents | M10: Not Started | N10: High | O10: 0 | P10: =IF(M10="Completed","Green",IF(TODAY()>H10,"Red",IF(AND(TODAY()+14>H10,O10<0.75),"Amber","Green"))) -> Green
A11: AIO-10 | B11: AIOps Implementation | C11: 31-60 Production Ready | D11: Define controlled auto-remediation candidate backlog and risk guardrails | E11: IBM SRE Lead | F11: Horizon Risk / Security | G11: 46248 | H11: 46262 | I11: =H11-G11+1 -> 15 | J11: AIO-08;AIO-09 | K11: Runbook automation backlog | L11: Low-risk candidates approved | M11: Not Started | N11: High | O11: 0 | P11: =IF(M11="Completed","Green",IF(TODAY()>H11,"Red",IF(AND(TODAY()+14>H11,O11<0.75),"Amber","Green"))) -> Green
A12: AIO-11 | B12: AIOps Implementation | C12: 61-90 Standardize & Integrate | D12: Standardize log, event and alert normalization across cloud applications | E12: IBM Observability Lead | F12: Horizon Monitoring Lead | G12: 46264 | H12: 46283 | I12: =H12-G12+1 -> 20 | J12: AIO-08;AIO-09 | K12: Standardized ingestion rules | L12: Consistent alert taxonomy across cloud apps | M12: Not Started | N12: High | O12: 0 | P12: =IF(M12="Completed","Green",IF(TODAY()>H12,"Red",IF(AND(TODAY()+14>H12,O12<0.75),"Amber","Green"))) -> Green
A13: AIO-12 | B13: AIOps Implementation | C13: 61-90 Standardize & Integrate | D13: Onboard remaining cloud applications and selected on-premise systems to AIOps ingestion | E13: IBM AIOps Lead | F13: Horizon App Owners | G13: 46268 | H13: 46292 | I13: =H13-G13+1 -> 25 | J13: AIO-11 | K13: Expanded AIOps onboarding | L13: Coverage expanded beyond pilot apps | M13: Not Started | N13: High | O13: 0 | P13: =IF(M13="Completed","Green",IF(TODAY()>H13,"Red",IF(AND(TODAY()+14>H13,O13<0.75),"Amber","Green"))) -> Green
A14: AIO-13 | B14: AIOps Implementation | C14: 61-90 Standardize & Integrate | D14: Enable AI-assisted recommendations for high-volume incident categories | E14: IBM AIOps Data Scientist | F14: Horizon Operations SMEs | G14: 46273 | H14: 46292 | I14: =H14-G14+1 -> 20 | J14: AIO-09;AIO-11 | K14: Recommendation engine pilot | L14: Recommendations available for priority incidents | M14: Not Started | N14: High | O14: 0 | P14: =IF(M14="Completed","Green",IF(TODAY()>H14,"Red",IF(AND(TODAY()+14>H14,O14<0.75),"Amber","Green"))) -> Green
... A21: AIO-20 | B21: AIOps Implementation | C21: 91-180 Scale & Optimize | D21: Complete 180-day AIOps value assessment and next-wave autonomous operations roadmap | E21: IBM AIOps Program Manager | F21: Horizon Executive Sponsor | G21: 46363 | H21: 46382 | I21: =H21-G21+1 -> 20 | J21: AIO-18;AIO-19 | K21: AIOps value assessment | L21: MTTR/noise/productivity progress captured | M21: Not Started | N21: High | O21: 0 | P21: =IF(M21="Completed","Green",IF(TODAY()>H21,"Red",IF(AND(TODAY()+14>H21,O21<0.75),"Amber","Green"))) -> Green

Sheet CareOps360
A1: ID | B1: Workstream | C1: Phase | D1: Task / Activity | E1: IBM Owner | F1: Horizon Owner | G1: Start Date | H1: End Date | I1: Duration Days | J1: Dependencies | K1: Deliverable / Milestone | L1: Success Metric | M1: Status | N1: Priority | O1: % Complete | P1: RAG | Q1: Notes
A2: CAR-01 | B2: CareOps360 | C2: 0-30 Foundation | D2: Secure CareOps360 MVP scope, executive dashboard personas and success criteria | E2: CareOps360 Product Owner | F2: Horizon Transformation Sponsor | G2: 46204 | H2: 46208 | I2: =H2-G2+1 -> 5 | K2: MVP scope and dashboard personas | L2: MVP personas and dashboard objectives approved | M2: Not Started | N2: High | O2: 0 | P2: =IF(M2="Completed","Green",IF(TODAY()>H2,"Red",IF(AND(TODAY()+14>H2,O2<0.75),"Amber","Green"))) -> Green
A3: CAR-02 | B3: CareOps360 | C3: 0-30 Foundation | D3: Obtain ARB Light approval and define MVP deployment architecture | E3: CareOps360 Architect | F3: Horizon ARB / Security | G3: 46206 | H3: 46213 | I3: =H3-G3+1 -> 8 | J3: CAR-01 | K3: ARB Light approval package | L3: MVP approval path clear | M3: Not Started | N3: High | O3: 0 | P3: =IF(M3="Completed","Green",IF(TODAY()>H3,"Red",IF(AND(TODAY()+14>H3,O3<0.75),"Amber","Green"))) -> Green
A4: CAR-03 | B4: CareOps360 | C4: 0-30 Foundation | D4: Deploy containerized CareOps360 to OCP/AWS dev environment | E4: CareOps360 Engineering Lead | F4: Horizon Platform Lead | G4: 46208 | H4: 46217 | I4: =H4-G4+1 -> 10 | J4: CAR-02 | K4: CareOps360 dev deployment | L4: Application deployed in dev | M4: Not Started | N4: High | O4: 0 | P4: =IF(M4="Completed","Green",IF(TODAY()>H4,"Red",IF(AND(TODAY()+14>H4,O4<0.75),"Amber","Green"))) -> Green
A5: CAR-04 | B5: CareOps360 | C5: 0-30 Foundation | D5: Provision RDS Postgres schema and baseline data model for dashboards | E5: CareOps360 Data Lead | F5: Horizon Data Owner | G5: 46211 | H5: 46220 | I5: =H5-G5+1 -> 10 | J5: CAR-02 | K5: Data schema and model | L5: Schema ready for MVP data loads | M5: Not Started | N5: High | O5: 0 | P5: =IF(M5="Completed","Green",IF(TODAY()>H5,"Red",IF(AND(TODAY()+14>H5,O5<0.75),"Amber","Green"))) -> Green
A6: CAR-05 | B6: CareOps360 | C6: 0-30 Foundation | D6: Manually load initial data for Executive Overview, Claims, Prior Auth and Providers views | E6: CareOps360 Data Lead | F6: Horizon Domain Owners | G6: 46213 | H6: 46227 | I6: =H6-G6+1 -> 15 | J6: CAR-04 | K6: Initial dashboard data loads | L6: MVP views populated | M6: Not Started | N6: High | O6: 0 | P6: =IF(M6="Completed","Green",IF(TODAY()>H6,"Red",IF(AND(TODAY()+14>H6,O6<0.75),"Amber","Green"))) -> Green
A7: CAR-06 | B7: CareOps360 | C7: 0-30 Foundation | D7: Configure dashboard layouts, KPI definitions and role-based page access | E7: CareOps360 Product Owner | F7: Horizon Business Owners | G7: 46218 | H7: 46229 | I7: =H7-G7+1 -> 12 | J7: CAR-01;CAR-05 | K7: MVP dashboard configuration | L7: Dashboard tiles and KPIs validated | M7: Not Started | N7: High | O7: 0 | P7: =IF(M7="Completed","Green",IF(TODAY()>H7,"Red",IF(AND(TODAY()+14>H7,O7<0.75),"Amber","Green"))) -> Green
A8: CAR-07 | B8: CareOps360 | C8: 0-30 Foundation | D8: Conduct MVP playback and prioritize production hardening backlog | E8: CareOps360 Product Owner | F8: Horizon Stakeholders | G8: 46228 | H8: 46237 | I8: =H8-G8+1 -> 10 | J8: CAR-03;CAR-06 | K8: MVP playback readout | L8: Feedback converted to backlog | M8: Not Started | N8: High | O8: 0 | P8: =IF(M8="Completed","Green",IF(TODAY()>H8,"Red",IF(AND(TODAY()+14>H8,O8<0.75),"Amber","Green"))) -> Green
A9: CAR-08 | B9: CareOps360 | C9: 31-60 Production Ready | D9: Promote MVP through Horizon release process with SSO and RBAC configured | E9: CareOps360 Engineering Lead | F9: Horizon Security / Release | G9: 46234 | H9: 46248 | I9: =H9-G9+1 -> 15 | J9: CAR-07 | K9: Production-ready MVP | L9: SSO/RBAC and release gates passed | M9: Not Started | N9: High | O9: 0 | P9: =IF(M9="Completed","Green",IF(TODAY()>H9,"Red",IF(AND(TODAY()+14>H9,O9<0.75),"Amber","Green"))) -> Green
A10: CAR-09 | B10: CareOps360 | C10: 31-60 Production Ready | D10: Design target-state near-real-time architecture with Kafka/MSK and data contracts | E10: CareOps360 Architect | F10: Horizon Data / Integration | G10: 46238 | H10: 46257 | I10: =H10-G10+1 -> 20 | J10: CAR-04;CAR-07 | K10: Target architecture | L10: Data contracts and integration pattern approved | M10: Not Started | N10: High | O10: 0 | P10: =IF(M10="Completed","Green",IF(TODAY()>H10,"Red",IF(AND(TODAY()+14>H10,O10<0.75),"Amber","Green"))) -> Green
A11: CAR-10 | B11: CareOps360 | C11: 31-60 Production Ready | D11: Obtain ARB approval for target CareOps360 architecture | E11: CareOps360 Architect | F11: Horizon ARB / Security | G11: 46248 | H11: 46262 | I11: =H11-G11+1 -> 15 | J11: CAR-09 | K11: ARB approval | L11: Target architecture approved | M11: Not Started | N11: High | O11: 0 | P11: =IF(M11="Completed","Green",IF(TODAY()>H11,"Red",IF(AND(TODAY()+14>H11,O11<0.75),"Amber","Green"))) -> Green
A12: CAR-11 | B12: CareOps360 | C12: 31-60 Production Ready | D12: Define CareOps360 operating model, support model and product ownership cadence | E12: CareOps360 Product Owner | F12: Horizon Product Owners | G12: 46253 | H12: 46262 | I12: =H12-G12+1 -> 10 | J12: CAR-08 | K12: CareOps360 operating model | L12: Backlog and release cadence active | M12: Not Started | N12: High | O12: 0 | P12: =IF(M12="Completed","Green",IF(TODAY()>H12,"Red",IF(AND(TODAY()+14>H12,O12<0.75),"Amber","Green"))) -> Green
A13: CAR-12 | B13: CareOps360 | C13: 61-90 Standardize & Integrate | D13: Build ingestion platform in AWS using infrastructure-as-code, MSK and observability tools | E13: CareOps360 Engineering Lead | F13: Horizon Platform Lead | G13: 46264 | H13: 46283 | I13: =H13-G13+1 -> 20 | J13: CAR-09;CAR-10 | K13: Automated ingestion platform | L13: IaC pipeline and MSK foundation built | M13: Not Started | N13: High | O13: 0 | P13: =IF(M13="Completed","Green",IF(TODAY()>H13,"Red",IF(AND(TODAY()+14>H13,O13<0.75),"Amber","Green"))) -> Green
A14: CAR-13 | B14: CareOps360 | C14: 61-90 Standardize & Integrate | D14: Automate top 4-6 sources including ServiceNow, APM and Databricks | E14: CareOps360 Data Lead | F14: Horizon Source Owners | G14: 46268 | H14: 46287 | I14: =H14-G14+1 -> 20 | J14: CAR-12 | K14: Automated source integrations | L14: Priority integrations automated | M14: Not Started | N14: High | O14: 0 | P14: =IF(M14="Completed","Green",IF(TODAY()>H14,"Red",IF(AND(TODAY()+14>H14,O14<0.75),"Amber","Green"))) -> Green
... A21: CAR-20 | B21: CareOps360 | C21: 91-180 Scale & Optimize | D21: Complete 180-day CareOps360 value review and next capability roadmap | E21: CareOps360 Product Owner | F21: Horizon Executive Sponsor | G21: 46363 | H21: 46382 | I21: =H21-G21+1 -> 20 | J21: CAR-17;CAR-19 | K21: CareOps360 180-day roadmap | L21: Adoption, value and next-wave capabilities approved | M21: Not Started | N21: High | O21: 0 | P21: =IF(M21="Completed","Green",IF(TODAY()>H21,"Red",IF(AND(TODAY()+14>H21,O21<0.75),"Amber","Green"))) -> Green

Sheet Agile Product Model
A1: ID | B1: Workstream | C1: Phase | D1: Task / Activity | E1: IBM Owner | F1: Horizon Owner | G1: Start Date | H1: End Date | I1: Duration Days | J1: Dependencies | K1: Deliverable / Milestone | L1: Success Metric | M1: Status | N1: Priority | O1: % Complete | P1: RAG | Q1: Notes
